nohup: ignoring input
/home/bvelasco/CovidVax_DM/covidvax_DM_pygformula.py:21: DtypeWarning: Columns (8,9,10,11,12,13,14,15,16,17) have mixed types. Specify dtype option on import or set low_memory=False.
  data = pd.read_csv('included_cohort_prep.csv')
joblib.externals.loky.process_executor._RemoteTraceback: 
"""
Traceback (most recent call last):
  File "/home/bvelasco/miniconda3/envs/python3.10/lib/python3.10/site-packages/joblib/externals/loky/process_executor.py", line 463, in _process_worker
    r = call_item()
  File "/home/bvelasco/miniconda3/envs/python3.10/lib/python3.10/site-packages/joblib/externals/loky/process_executor.py", line 291, in __call__
    return self.fn(*self.args, **self.kwargs)
  File "/home/bvelasco/miniconda3/envs/python3.10/lib/python3.10/site-packages/joblib/parallel.py", line 598, in __call__
    return [func(*args, **kwargs)
  File "/home/bvelasco/miniconda3/envs/python3.10/lib/python3.10/site-packages/joblib/parallel.py", line 598, in <listcomp>
    return [func(*args, **kwargs)
  File "/home/bvelasco/miniconda3/envs/python3.10/lib/python3.10/site-packages/pygformula-1.0.3-py3.10.egg/pygformula/parametric_gformula/simulate.py", line 375, in simulate
    prediction = covariate_fits[cov].predict(new_df[covar_model_vars])
  File "/home/bvelasco/miniconda3/envs/python3.10/lib/python3.10/site-packages/sklearn/ensemble/_forest.py", line 1064, in predict
    X = self._validate_X_predict(X)
  File "/home/bvelasco/miniconda3/envs/python3.10/lib/python3.10/site-packages/sklearn/ensemble/_forest.py", line 641, in _validate_X_predict
    X = self._validate_data(
  File "/home/bvelasco/miniconda3/envs/python3.10/lib/python3.10/site-packages/sklearn/base.py", line 608, in _validate_data
    self._check_feature_names(X, reset=reset)
  File "/home/bvelasco/miniconda3/envs/python3.10/lib/python3.10/site-packages/sklearn/base.py", line 535, in _check_feature_names
    raise ValueError(message)
ValueError: The feature names should match those that were passed during fit.
Feature names must be in the same order as they were in fit.

"""

The above exception was the direct cause of the following exception:

Traceback (most recent call last):
  File "/home/bvelasco/CovidVax_DM/covidvax_DM_pygformula.py", line 148, in <module>
    g.fit()
  File "/home/bvelasco/miniconda3/envs/python3.10/lib/python3.10/site-packages/pygformula-1.0.3-py3.10.egg/pygformula/parametric_gformula/parametric_gformula.py", line 553, in fit
    Parallel(n_jobs=self.ncores) # Consider trying prefer="threads"  prefer="threads"
  File "/home/bvelasco/miniconda3/envs/python3.10/lib/python3.10/site-packages/joblib/parallel.py", line 2007, in __call__
    return output if self.return_generator else list(output)
  File "/home/bvelasco/miniconda3/envs/python3.10/lib/python3.10/site-packages/joblib/parallel.py", line 1650, in _get_outputs
    yield from self._retrieve()
  File "/home/bvelasco/miniconda3/envs/python3.10/lib/python3.10/site-packages/joblib/parallel.py", line 1754, in _retrieve
    self._raise_error_fast()
  File "/home/bvelasco/miniconda3/envs/python3.10/lib/python3.10/site-packages/joblib/parallel.py", line 1789, in _raise_error_fast
    error_job.get_result(self.timeout)
  File "/home/bvelasco/miniconda3/envs/python3.10/lib/python3.10/site-packages/joblib/parallel.py", line 745, in get_result
    return self._return_or_raise()
  File "/home/bvelasco/miniconda3/envs/python3.10/lib/python3.10/site-packages/joblib/parallel.py", line 763, in _return_or_raise
    raise self._result
ValueError: The feature names should match those that were passed during fit.
Feature names must be in the same order as they were in fit.

/home/bvelasco/miniconda3/envs/python3.10/lib/python3.10/site-packages/joblib/externals/loky/backend/resource_tracker.py:314: UserWarning: resource_tracker: There appear to be 471 leaked file objects to clean up at shutdown
  warnings.warn(
